<mujoco>

  <worldbody>
    <light pos="0 0 1.5" dir="0 0 -1" directional="true"/>
    <geom name="floor" size="0 0 0.05" type="plane" material="groundplane" friction=".5 0.005 0.001"  priority="2" condim="4"/>
  </worldbody>



    <worldbody>

  <!--       <light pos="0 0 1"/> -->
  <!--       <light pos="0 -0.2 1" dir="0 0.2 -0.8" directional="true"/> -->
		<!---->
        <!-- Define the environment -->
  <!--       <body name="floor" pos="0 0 0" friction=".0 .0 .0 .0 .0"> -->
		<!-- <geom name="floor_geom" type="plane" material="groundplane"   /> -->
  <!--       </body> -->

        <body name="case" pos="0 0 0.01">
		<geom name="gcase_a" type="box" size="0.02 0.3 0.01" pos=".4 0 0" />
		<geom name="gcase_b" type="box" size="0.02 0.3 0.01" pos="-.4 0 0" />
		<geom name="gcase_c" type="box" size="0.35 0.04 0.01" pos="0 .4 0" />
		<geom name="gcase_d" type="box" size="0.35 0.04 0.01" pos="0 -.4 0" />
        </body>


        <body name="cube" pos="0 0 .05">
	<freejoint/>
            <geom  name = "gcube_0" type="box" size="0.05 0.05 0.05" mass=".1" material="CubeMat" condim="4"  />
           <site name="sensor_box" />
        </body>

        <body name="ball" pos=".3 0 .05">
                <geom name="gball_0" type="sphere" size="0.02" mass="1." material="BallMat" friction=".5 0.005 0.001 " condim="4"  />
            <site name="sensor_ball" />
            <joint name="joint_x" type="slide" pos="0 0 0" axis="1 0 0"/>
            <joint name="joint_y" type="slide" pos="0 0 0" axis="0 1 0"/>
            <!-- <joint name="joint_z" type="slide" pos="0 0 0" axis="0 0 1"/> -->
        </body>

    </worldbody>

    <actuator>
        <motor name="actuator_x" joint="joint_x" gear="1"/>
        <motor name="actuator_y" joint="joint_y" gear="1"/>
    </actuator>

    <asset>
        <!-- Materials for visualization -->
        <material name="MatPlane" rgba="0.8 0.9 0.8 1"/>
        <material name="CubeMat" rgba="0.8 0.2 0.2 1"/>
        <material name="BallMat" rgba="0.2 0.2 0.8 1"/>

    <texture type="skybox" builtin="gradient" rgb1="0.3 0.5 0.7" rgb2="0 0 0" width="512" height="3072"/>
    <texture type="2d" name="groundplane" builtin="checker" mark="edge" rgb1="0.2 0.3 0.4" rgb2="0.1 0.2 0.3"
      markrgb="0.8 0.8 0.8" width="300" height="300"/>
    <material name="groundplane" texture="groundplane" texuniform="true" texrepeat="5 5" reflectance="0.2"/>
    </asset>

      <visual>
        <headlight diffuse="0.6 0.6 0.6" ambient="0.3 0.3 0.3" specular="0 0 0"/>
        <rgba haze="0.15 0.25 0.35 1"/>
        <global azimuth="60" elevation="-20"/>
      </visual>


  <sensor>
      <velocimeter name="sensor_box" site="sensor_box"/>
      <velocimeter name="sensor_ball" site="sensor_ball"/>
  </sensor>



</mujoco>
